Workbook

Sheet สรุป
A1: สรุปกำไร — QT26088462 (ตรงกับกล่อง 'สรุปกำไร' บนหน้าจอ)
A3: # | B3: รายการ | C3: จำนวน (บาท) | D3: ที่มา / วิธีคิด
A4: 1 | B4: ยอดค่าขายรับมา | C4: =วิธีคิดทีละขั้น!D9 -> 37776 | D4: ราคาขายต่อท่าน 18,888.00 × 2 ท่าน
A5: 2 | B5: ต้นทุนโฮลเซลล์ | C5: =วิธีคิดทีละขั้น!D10 -> 36147.96 | D5: ราคาที่ซื้อจากบริษัทโฮลเซลล์ (18,073.98 ต่อท่าน)
A6: 3 | B6: ชำระโฮลเซลล์แล้ว | C6: =การชำระเงิน!E5 -> 36147.96 | D6: จ่ายจริงตามรายการ WS26080615 วันที่ 28/08/2026
A7: 4 | B7: ค้างจ่ายโฮลเซลล์ | C7: =วิธีคิดทีละขั้น!D10-การชำระเงิน!E5 -> 0 | D7: ต้นทุนโฮลเซลล์ − ที่จ่ายแล้ว = 0.00 (ปิดยอดครบ)
A8: 5 | B8: ต้นทุนอื่น | C8: =วิธีคิดทีละขั้น!D32 -> 132.71 | D8: ภาษีขาย 104.67 + ภาษีหัก ณ ที่จ่าย 28.04
A9: 6 | B9: กำไรขั้นต้น (ก่อนภาษี) | C9: =วิธีคิดทีละขั้น!D16 -> 1628.04 | D9: ยอดขาย − ต้นทุนโฮลเซลล์
A10: 7 | B10: กำไรสุทธิ | C10: =วิธีคิดทีละขั้น!D37 -> 1495.33 | D10: ยอดขาย − ต้นทุนโฮลเซลล์ − ต้นทุนอื่น
A11: 8 | B11: อัตรากำไรสุทธิ | C11: =วิธีคิดทีละขั้น!D38 -> 0.039584127 | D11: กำไรสุทธิ ÷ ยอดขาย
A12: 9 | B12: กำไรสุทธิต่อท่าน | C12: =วิธีคิดทีละขั้น!D39 -> 747.665 | D12: กำไรสุทธิ ÷ 2 ท่าน
B14: สมการเดียวจบ
B15: 37,776.00 − 36,147.96 − 104.67 − 28.04 = 1,495.33 บาท
B21: 1 | C21: ยอดค่าขายรับมา
B36: 2 | C36: ต้นทุนโฮลเซลล์
B49: 3 | C49: ชำระโฮลเซลล์แล้ว
B63: 4 | C63: ค้างจ่ายโฮลเซลล์ | D63: =วิธีคิดทีละขั้น!E66-การชำระเงิน!F61 -> 0 | E63: ต้นทุนโฮลเซลล์ − ที่จ่ายแล้ว = 0.00 (ปิดยอดครบ)
B67: 5 | C67: ต้นทุนอื่น | D67: =วิธีคิดทีละขั้น!E91 -> 0
B82: อธิบาย รายการต้นทุนเพิ่ม
B83: ต้นทุนส่วนนี้ประกอบไปด้วย
B84: 1. ยอดหัก ณ ที่จ่าย (ลูกค้าหักเรา จ่ายเงินไม่ครบ) หากลูกค้าหักเรา และไม่มีใบหักมาให้ ส่วนนี้จะถือว่าเป็นต้นทุน แต่ถ้ามีมาแนบจะไม่เอาไปคิด
B85: 1. ต้นทุนภาษีขาย (ฝั่งของเรา) คิดภาษีจากกำไร
B86: 2. ต้นทุนภาษีซื้อ (ฝั่งของโฮลเซลล์) หากเราได้ใบกำกับภาษีโฮลเซลล์มา จะถือว่าเคลมคืนได้ ก็จะเอายอดส่วนนี้มาลบกับภาษีขายของบริษัท
B87: 3.ต้นทุนอื่นๆ เช่น ค่าพนักงานไปส่งลูกค้าสนามบิน ,ค่าซื้อของแจก,ค่าธรรมเนียมรูดบัตรที่จ่ายแทนลูกค้า ถือว่าเป็นต้นทุน
B88: 4. ภาษีหัก ณ ที่จ่าย จะเป็นต้นทุน เมื่อมีการออกเอกสารหัก ซึ่งบางโฮลเซลล์จะไม่ได้หัก เพราะไม่ได้เข้าระบบภาษี ส่วนนี้หักได้บางบริษัท
L90: รวม
E91: หัก ณ ที่จ่าย (ลูกค้า หักเรา) | J91: N/A
E92: ภาษีขาย | J92: 104.67 | L92: 104.67 | M92: หากมีไฟล์แนบจะเอา (ภาษีซื้อ-ภาษีขาย)+ยอดหัก ณ ที่จ่าย ที่ลูกค้าหักเรา จะได้ยอดรวม แต่ถ้าไม่มีไฟล์แนบ จะเอาแค่ยอดภาษีขาย+ยอดหัก ณ ที่จ่ายที่ลูกค้าหักเรา ได้ยอดรวม
E93: ภาษีซื้อ | I93: 65.42
E94: หัก ณ ที่จ่าย (เราหัก โฮลเซลล์) | J94: 28.04 | L94: 28.04
E95: ต้นทุนอื่นๆ | J95: 0 | L95: 0
I98: ยอดรวมทั้งหมด | L98: เอาช่องยอดรวมมา+กัน
B137: 6 | C137: กำไรขั้นต้น (ก่อนภาษี) | D137: =วิธีคิดทีละขั้น!E92 -> 0
B138: 7 | C138: กำไรสุทธิ | D138: =วิธีคิดทีละขั้น!E113 -> 0

Sheet ข้อมูลเอกสาร
A1: ข้อมูลเอกสาร / ลูกค้า / การจอง / แพคเกจ
A3: หัวข้อ | B3: ค่า | C3: หมายเหตุ
A4: — เอกสาร —
A5: เลขที่ใบเสนอราคา | B5: QT26088462
A6: วันที่ออกเอกสาร | B6: 27 ส.ค. 2569 13:25 | C6: พ.ศ. 2569 = ค.ศ. 2026
A7: — ลูกค้า —
A8: รหัสลูกค้า | B8: CUS-26087195
A9: ชื่อลูกค้า | B9: ศุภกร ศรีบวรบุญ… | C9: อ่านจากภาพ ความละเอียดต่ำ — ควรยืนยันสะกดกับระบบ
A10: อีเมล | B10: supakorn.sri…@krungsri.com | C10: อ่านจากภาพ — ควรยืนยันกับระบบ
A11: เบอร์โทร | B11: 064-652-8955
A12: LINE | B12: Bam_Krungsri#519
A13: เลขผู้เสียภาษี / ที่อยู่ | B13: ไม่ระบุ (-) | C13: หากลูกค้าขอใบกำกับภาษีเต็มรูป ต้องเก็บข้อมูลนี้เพิ่ม
A14: — การจอง —
A15: Booking No. | B15: BK26088457
A16: รหัสทัวร์ | B16: JP0909261140
A17: พนักงานขาย | B17: เมธาพัชร์ ตันตระกูล (ปั้น) | C17: อ่านจากภาพ
A18: วันที่เสนอราคา | B18: 27 ส.ค. 2569
A19: แก้ไขล่าสุด | B19: 28/08/2026 09:57 โดย วนิษา จิตรมล (แอน)
A20: — แพคเกจ —
A21: ชื่อแพคเกจ | B21: XJ357 ทัวร์ญี่ปุ่น TOKYO FUJI SUMMER FREEDAY 6D4N
A22: สายการบิน | B22: Air Asia X (XJ)
A23: วันเดินทาง | B23: 9 ก.ย. 2569 – 14 ก.ย. 2569 | C23: ระบุ 6 วัน 4 คืน (ปกติคือบินดึกคืนแรก)
A24: ผู้เดินทาง | B24: 2 ท่าน
A25: โฮลเซลล์ | B25: บริษัทโฮลเซลล์ผู้จัดทัวร์ | C25: ชื่อบริษัทในภาพอ่านไม่ชัด — ควรยืนยันกับระบบ
A26: — สถานะการเงิน —
A27: ราคาขาย | B27: 37,776.00 บาท
A28: กำหนดชำระมัดจำ | B28: 28 ส.ค. 2569 — 0.00 บาท | C28: ไม่มีการเก็บมัดจำ
A29: กำหนดชำระเต็มจำนวน | B29: 27 ส.ค. 2569 — 37,776.00 บาท | C29: วันครบกำหนดเต็มมาก่อนวันมัดจำ 1 วัน (ดูข้อสังเกต)
A30: สถานะ | B30: ชำระเงินครบแล้ว

Sheet วิธีคิดทีละขั้น
A1: วิธีคิดทีละขั้น — เอกสาร QT26088462 / Booking BK26088457
A2: ที่มาข้อมูล: ภาพหน้าจอระบบหลังบ้าน Next Trip Holiday ที่ผู้ใช้อัปโหลด (27–28 ส.ค. 2569)
A3: สีน้ำเงิน = ค่าตั้งต้นที่กรอกเอง (แก้ได้) | สีดำ = สูตรคำนวณในชีตนี้ | สีเขียว = ลิงก์จากชีตอื่น
A5: ขั้นที่ | B5: รายการ | C5: สูตร / ที่มา | D5: จำนวน (บาท) | E5: หมายเหตุ
A6: ก. ข้อมูลตั้งต้น (Input)
A7: ก.1 | B7: ราคาขายต่อท่าน | C7: กรอกเอง — อนุมานจาก 37,776.00 ÷ 2 ท่าน | D7: 18888 | E7: ราคาที่เสนอลูกค้า
A8: ก.2 | B8: จำนวนผู้เดินทาง (ท่าน) | C8: กรอกเอง — จากรายละเอียดแพคเกจ | D8: 2
A9: ก.3 | B9: ราคาขายรวม (ยอดค่าขายรับมา) | C9: ก.1 × ก.2 | D9: =D7*D8 -> 37776 | E9: ตรงกับ 'ราคาขาย 37,776.00 บาท' บนหน้าจอ
A10: ก.4 | B10: ต้นทุนโฮลเซลล์รวม | C10: กรอกเอง — จากช่อง 'ต้นทุนโฮลเซลล์' | D10: 36147.96 | E10: บริษัทโฮลเซลล์ผู้จัดทัวร์
A11: ก.5 | B11: ต้นทุนโฮลเซลล์ต่อท่าน | C11: ก.4 ÷ ก.2 | D11: =D10/D8 -> 18073.98
A12: ก.6 | B12: อัตราภาษีมูลค่าเพิ่ม (VAT) | C12: กรอกเอง — อัตราตามกฎหมาย | D12: 0.07
A13: ก.7 | B13: อัตราภาษีหัก ณ ที่จ่าย | C13: กรอกเอง — ค่าบริการทั่วไป 3% | D13: 0.03 | E13: อนุมานจาก 28.04 ÷ 934.58 = 3.00%
A14: ก.8 | B14: ยอดใบกำกับภาษีซื้อ 260827-020 (รวม VAT) | C14: กรอกเอง — อนุมานจาก 934.58 + 65.42 | D14: 1000 | E14: ยอดกลม 1,000 บาท
A15: ข. กำไรขั้นต้น (ก่อนภาษี)
A16: ข.1 | B16: กำไรขั้นต้น | C16: ก.3 − ก.4 | D16: =D9-D10 -> 1628.04 | E16: 37,776.00 − 36,147.96
A17: ข.2 | B17: กำไรขั้นต้นต่อท่าน | C17: ข.1 ÷ ก.2 | D17: =D16/D8 -> 814.02
A18: ข.3 | B18: อัตรากำไรขั้นต้นต่อราคาขาย | C18: ข.1 ÷ ก.3 | D18: =D16/D9 -> 0.043097205
A19: ค. ฝั่งภาษีซื้อ — ใบกำกับเลขที่ 260827-020
A20: ค.1 | B20: ฐานค่าบริการ (ไม่รวม VAT) | C20: ก.8 ÷ (1 + ก.6) | D20: =ROUND(D14/(1+D12),2) -> 934.58 | E20: 1,000.00 ÷ 1.07 = 934.58
A21: ค.2 | B21: ภาษีซื้อ 7% | C21: ปัดทศนิยม 2 (ค.1 × ก.6) | D21: =ROUND(D20*D12,2) -> 65.42 | E21: 934.58 × 7% = 65.42
A22: ค.3 | B22: ตรวจ: ค.1 + ค.2 ต้องเท่ากับ ก.8 | C22: ค.1 + ค.2 | D22: =D20+D21 -> 1000 | E22: ต้องได้ 1,000.00
A23: ค.4 | B23: ภาษีหัก ณ ที่จ่าย 3% | C23: ปัดทศนิยม 2 (ค.1 × ก.7) | D23: =ROUND(D20*D13,2) -> 28.04 | E23: 934.58 × 3% = 28.04 → นับเป็นต้นทุน
A24: ง. ฝั่งภาษีขาย — ใบกำกับเลขที่ IVN2608-0528
A25: ง.1 | B25: ยอดที่นำมาออกใบกำกับภาษีขาย (รวม VAT) | C25: ข.1 − ค.4 | D25: =D16-D23 -> 1600 | E25: 1,628.04 − 28.04 = 1,600.00 พอดี
A26: ง.2 | B26: ฐานค่าบริการ (ไม่รวม VAT) | C26: ปัดทศนิยม 2 (ง.1 ÷ (1 + ก.6)) | D26: =ROUND(D25/(1+D12),2) -> 1495.33 | E26: 1,600.00 ÷ 1.07 = 1,495.33
A27: ง.3 | B27: ภาษีขาย 7% | C27: ปัดทศนิยม 2 (ง.2 × ก.6) | D27: =ROUND(D26*D12,2) -> 104.67 | E27: 1,495.33 × 7% = 104.67 → นับเป็นต้นทุน
A28: ง.4 | B28: ตรวจ: ง.2 + ง.3 ต้องเท่ากับ ง.1 | C28: ง.2 + ง.3 | D28: =D26+D27 -> 1600 | E28: ต้องได้ 1,600.00
A29: จ. ต้นทุนอื่น (ช่อง 'ต้นทุนอื่น' = 132.71)
A30: จ.1 | B30: ภาษีขาย 7% (แถวภาษีขาย) | C30: ง.3 | D30: =D27 -> 104.67
A31: จ.2 | B31: ภาษีหัก ณ ที่จ่าย 3% (แถวภาษีซื้อ) | C31: ค.4 | D31: =D23 -> 28.04
A32: จ.3 | B32: รวมต้นทุนอื่น | C32: จ.1 + จ.2 | D32: =D30+D31 -> 132.71 | E32: 104.67 + 28.04 = 132.71
A33: ฉ. กำไรสุทธิ
A34: ฉ.1 | B34: ราคาขายรวม | C34: ก.3 | D34: =D9 -> 37776
A35: ฉ.2 | B35: หัก ต้นทุนโฮลเซลล์ | C35: − ก.4 | D35: =-D10 -> -36147.96
A36: ฉ.3 | B36: หัก ต้นทุนอื่น | C36: − จ.3 | D36: =-D32 -> -132.71
A37: ฉ.4 | B37: กำไรสุทธิ | C37: ฉ.1 + ฉ.2 + ฉ.3 | D37: =SUM(D34:D36) -> 1495.33 | E37: ตรงกับ 1,495.33 บนหน้าจอ
A38: ฉ.5 | B38: อัตรากำไรสุทธิต่อราคาขาย | C38: ฉ.4 ÷ ก.3 | D38: =D37/D9 -> 0.039584127
A39: ฉ.6 | B39: กำไรสุทธิต่อท่าน | C39: ฉ.4 ÷ ก.2 | D39: =D37/D8 -> 747.665
B41: ข้อสังเกตสำคัญของสูตร
B42: 1) ระบบคิดภาษีขาย 7% จาก 'ส่วนต่างกำไร' ไม่ใช่จากราคาทัวร์เต็ม 37,776 บาท (ตัวแทนท่องเที่ยวออกใบกำกับเฉพาะค่าบริการ/คอมมิชชั่น)
...

Sheet รายการภาษี
A1: รายการต้นทุนภาษี — ถอดสูตรทีละแถว
A3: # | B3: ประเภท | C3: เลขที่เอกสาร | D3: ค่าบริการ (ฐาน) | E3: ยอดรวม VAT | F3: ภาษีหัก ณ ที่จ่าย 3% | G3: ภาษี 7% | H3: ยอดที่นับเป็นต้นทุน | I3: วิธีคิด
A4: 1 | B4: ภาษีขาย | C4: IVN2608-0528 | D4: =วิธีคิดทีละขั้น!D26 -> 1495.33 | E4: =วิธีคิดทีละขั้น!D25 -> 1600 | F4: 0 | G4: =วิธีคิดทีละขั้น!D27 -> 104.67 | H4: =วิธีคิดทีละขั้น!D27 -> 104.67 | I4: ฐาน = (กำไรขั้นต้น 1,628.04 − WHT 28.04) ÷ 1.07 = 1,495.33 ; VAT = 1,495.33 × 7% = 104.67 ; นับ VAT เป็นต้นทุน
A5: 2 | B5: ภาษีซื้อ | C5: 260827-020 | D5: =วิธีคิดทีละขั้น!D20 -> 934.58 | E5: =วิธีคิดทีละขั้น!D14 -> 1000 | F5: =วิธีคิดทีละขั้น!D23 -> 28.04 | G5: =วิธีคิดทีละขั้น!D21 -> 65.42 | H5: =วิธีคิดทีละขั้น!D23 -> 28.04 | I5: ฐาน = 1,000.00 ÷ 1.07 = 934.58 ; VAT = 65.42 ; WHT = 934.58 × 3% = 28.04 ; นับ WHT เป็นต้นทุน
C6: รวม | H6: =SUM(H4:H5) -> 132.71 | I6: 104.67 + 28.04 = 132.71 → ไปเข้าช่อง 'ต้นทุนอื่น' ในกล่องสรุปกำไร
A8: ภาระภาษีจริงที่ต้องดูเพิ่ม (ไม่ได้แสดงบนหน้าจอ)
A9: ภาษีขาย (Output VAT) | D9: =วิธีคิดทีละขั้น!D27 -> 104.67 | E9: ยอดที่ต้องนำส่งกรมสรรพากร
A10: หัก ภาษีซื้อ (Input VAT) | D10: =-วิธีคิดทีละขั้น!D21 -> -65.42 | E10: เครดิตภาษีซื้อ หากใบกำกับถูกต้องและเป็นค่าใช้จ่ายของกิจการ
A11: VAT สุทธิที่ต้องนำส่ง | D11: =วิธีคิดทีละขั้น!D27-วิธีคิดทีละขั้น!D21 -> 39.25 | E11: 104.67 − 65.42 = 39.25 บาท

Sheet การชำระเงิน
A1: กระแสเงินสด — รับจากลูกค้า / จ่ายโฮลเซลล์
A3: # | B3: รายการ | C3: อ้างอิง / วันที่ | D3: รับเข้า (บาท) | E3: จ่ายออก (บาท) | F3: หมายเหตุ
A4: 1 | B4: รับชำระจากลูกค้า | C4: กำหนดชำระเต็ม 27 ส.ค. 2569 | D4: 37776 | F4: สถานะบนหน้าจอ: ชำระเงินครบแล้ว (มัดจำ 0.00 บาท)
A5: 2 | B5: จ่ายค่าทัวร์ให้โฮลเซลล์ | C5: WS26080615 · 28/08/2026 11:52 | E5: 36147.96 | F5: ประเภท: ชำระเงินโอน · แนบสลิป WS26080615_20260828.jpg
B6: รวม | D6: =SUM(D4:D5) -> 37776 | E6: =SUM(E4:E5) -> 36147.96
B8: เงินสดคงเหลือในมือ (ก่อนภาษี) | D8: =D6-E6 -> 1628.04 | F8: 37,776.00 − 36,147.96 = 1,628.04 = กำไรขั้นต้น
B9: หัก ต้นทุนภาษี (VAT + WHT) | D9: =-วิธีคิดทีละขั้น!D32 -> -132.71 | F9: 104.67 + 28.04 = 132.71
B10: เหลือสุทธิ | D10: =D6-E6-วิธีคิดทีละขั้น!D32 -> 1495.33 | F10: 1,495.33 บาท = กำไรสุทธิ
B11: ค้างจ่ายโฮลเซลล์ | D11: =วิธีคิดทีละขั้น!D10-E6 -> 0 | F11: 0.00 บาท — ปิดยอดครบ

Sheet ตรวจสอบและข้อสังเกต
A1: ตรวจสอบตัวเลข + ประเด็นที่ควรตรวจกับทีม
A3: # | B3: รายการตรวจสอบ | C3: ค่าที่คำนวณได้ | D3: ค่าที่หน้าจอแสดง | E3: ผล | F3: หมายเหตุ
A4: 1 | B4: ราคาขายรวม | C4: =วิธีคิดทีละขั้น!D9 -> 37776 | D4: 37776 | E4: =IF(ROUND(C4-D4,2)=0,"ตรงกัน","ต่าง "&TEXT(C4-D4,"0.00")) -> ตรงกัน | F4: ตรงกับที่หน้าจอแสดง
A5: 2 | B5: กำไรขั้นต้น (ขาย − โฮลเซลล์) | C5: =วิธีคิดทีละขั้น!D16 -> 1628.04 | D5: 1628.04 | E5: =IF(ROUND(C5-D5,2)=0,"ตรงกัน","ต่าง "&TEXT(C5-D5,"0.00")) -> ตรงกัน | F5: ไม่ได้แสดงบนหน้าจอ แต่เป็นตัวตั้งของการคิดภาษี
A6: 3 | B6: ฐานภาษีขาย | C6: =วิธีคิดทีละขั้น!D26 -> 1495.33 | D6: 1495.33 | E6: =IF(ROUND(C6-D6,2)=0,"ตรงกัน","ต่าง "&TEXT(C6-D6,"0.00")) -> ตรงกัน | F6: ตรงกับคอลัมน์ 'ค่าบริการ' แถวภาษีขาย
A7: 4 | B7: ภาษีขาย 7% | C7: =วิธีคิดทีละขั้น!D27 -> 104.67 | D7: 104.67 | E7: =IF(ROUND(C7-D7,2)=0,"ตรงกัน","ต่าง "&TEXT(C7-D7,"0.00")) -> ตรงกัน | F7: ตรงกับคอลัมน์ 'ภาษี 7%' แถวภาษีขาย
A8: 5 | B8: ฐานภาษีซื้อ | C8: =วิธีคิดทีละขั้น!D20 -> 934.58 | D8: 934.58 | E8: =IF(ROUND(C8-D8,2)=0,"ตรงกัน","ต่าง "&TEXT(C8-D8,"0.00")) -> ตรงกัน | F8: ตรงกับคอลัมน์ 'ค่าบริการ' แถวภาษีซื้อ
A9: 6 | B9: ภาษีซื้อ 7% | C9: =วิธีคิดทีละขั้น!D21 -> 65.42 | D9: 65.42 | E9: =IF(ROUND(C9-D9,2)=0,"ตรงกัน","ต่าง "&TEXT(C9-D9,"0.00")) -> ตรงกัน | F9: ตรงกับคอลัมน์ 'ภาษี 7%' แถวภาษีซื้อ
A10: 7 | B10: ภาษีหัก ณ ที่จ่าย 3% | C10: =วิธีคิดทีละขั้น!D23 -> 28.04 | D10: 28.04 | E10: =IF(ROUND(C10-D10,2)=0,"ตรงกัน","ต่าง "&TEXT(C10-D10,"0.00")) -> ตรงกัน | F10: ตรงกับคอลัมน์ 'ภาษีหัก' แถวภาษีซื้อ
A11: 8 | B11: รวมต้นทุนอื่น | C11: =วิธีคิดทีละขั้น!D32 -> 132.71 | D11: 132.71 | E11: =IF(ROUND(C11-D11,2)=0,"ตรงกัน","ต่าง "&TEXT(C11-D11,"0.00")) -> ตรงกัน | F11: ตรงกับยอดรวมท้ายตารางต้นทุน และช่อง 'ต้นทุนอื่น'
A12: 9 | B12: กำไรสุทธิ | C12: =วิธีคิดทีละขั้น!D37 -> 1495.33 | D12: 1495.33 | E12: =IF(ROUND(C12-D12,2)=0,"ตรงกัน","ต่าง "&TEXT(C12-D12,"0.00")) -> ตรงกัน | F12: ตรงกับช่องกำไรสุทธิในกล่องสรุปกำไร
A13: 10 | B13: ชำระโฮลเซลล์แล้ว | C13: =การชำระเงิน!E5 -> 36147.96 | D13: 36147.96 | E13: =IF(ROUND(C13-D13,2)=0,"ตรงกัน","ต่าง "&TEXT(C13-D13,"0.00")) -> ตรงกัน | F13: ตรงกับตารางรายการชำระเงินโฮลเซลล์
A16: ประเด็นที่ควรตรวจ
A17: # | B17: ประเด็น | C17: ระดับ | D17: ตัวเลข | F17: สิ่งที่ควรทำ
A18: 1 | B18: หัวตาราง 'รายการต้นทุน ภาษีมูลค่าเพิ่ม VAT + หัก ณ ที่จ่าย : 104.67 บาท' ไม่ตรงกับยอดรวมท้ายตาราง 132.71 บาท | C18: สูง | D18: ต่างกัน 28.04 | F18: ตรวจสูตรที่หัวตารางในโค้ด — ดูเหมือนรวมเฉพาะแถวภาษีขาย ไม่ได้บวกภาษีหัก ณ ที่จ่ายของแถวภาษีซื้อ
A19: 2 | B19: ภาษีซื้อ 65.42 บาท ไม่ถูกนำมาหักกลบภาษีขาย 104.67 บาท ในการคิดกำไร | C19: สูง | D19: กระทบ 65.42 | F19: ถ้าเครดิตภาษีซื้อได้ VAT ที่นำส่งจริงคือ 39.25 บาท และกำไรสุทธิควรเป็น 1,560.75 บาท — ตกลงนโยบายบัญชีให้ชัดก่อนแก้สูตร
A20: 3 | B20: ค่าบริการภาษีซื้อ 934.58 บาท ถูกนับเป็นต้นทุนแค่ 28.04 บาท (เฉพาะ WHT) ตัวค่าบริการเองไม่ถูกหักจากกำไร | C20: สูง | D20: กระทบ 934.58 | F20: ถ้ารายการ 1,000 บาทนี้เป็นค่าใช้จ่ายจริงของงานนี้ กำไรสุทธิจะเหลือราว 560.75 บาท — ต้องยืนยันว่ารายจ่ายนี้รวมอยู่ในต้นทุนโฮลเซลล์แล้วหรือยัง
A21: 4 | B21: กำหนดชำระเต็มจำนวน (27 ส.ค. 2569) มาก่อนกำหนดชำระมัดจำ (28 ส.ค. 2569) | C21: กลาง | D21: — | F21: ตรวจ logic การตั้งวันครบกำหนดเมื่อยอดมัดจำเป็น 0
A22: 5 | B22: ป้าย 'InputTax' ในบรรทัดดีบักเก็บค่าต้นทุนโฮลเซลล์ 36,147.96 ไม่ใช่ภาษีซื้อ | C22: กลาง | D22: — | F22: เปลี่ยนชื่อตัวแปร/ป้ายให้ตรงความหมาย กันสับสนตอนตรวจบัญชี
A23: 6 | B23: ระบบใช้ พ.ศ. กับวันที่ในเอกสาร แต่ใช้ ค.ศ. กับ timestamp (2569 vs 2026) | C23: ต่ำ | D23: — | F23: รวมรูปแบบวันที่ให้เป็นมาตรฐานเดียว หรืออย่างน้อยกำกับหน่วยปีให้ชัด
A24: 7 | B24: แถวภาษีขายยังไม่ได้แนบไฟล์เอกสาร (ช่อง Choose File ว่าง) | C24: ต่ำ | D24: — | F24: แนบไฟล์ใบกำกับ IVN2608-0528 ให้ครบก่อนปิดงาน
A25: 8 | B25: เลขผู้เสียภาษีและที่อยู่ลูกค้าเว้นว่าง | C25: ต่ำ | D25: — | F25: ถ้าลูกค้าต้องการใบกำกับภาษีเต็มรูป ต้องเก็บข้อมูลนี้ก่อนออกเอกสาร
B27: ตัวเลขทั้งหมดอ่านจากภาพหน้าจอที่อัปโหลด ไม่ได้ดึงจากฐานข้อมูล — ข้อความภาษาไทยบางจุด (ชื่อลูกค้า ชื่อโฮลเซลล์) ความละเอียดต่ำ ควรยืนยันกับระบบก่อนใช้อ้างอิง
